Workbook
Name a: '[2]main menu'!$H$4
Name ACD: '[4]data - main'!$AN$4
Name active_forex: '[4]info - forex'!$J$9
Name as: '[2]main menu'!$H$4
Name availability: '[4]data - PB avail'!$E$5:$AB$508
Name bt_did_mrp: '[4]quote - site BT services'!$Q$18:$Q$217
Name bt_did_otp: '[4]quote - site BT services'!$N$18:$N$217
Name bt_did_zone: '[4]quote - site BT services'!$AQ$18:$AQ$217
Name bt_req_did_mrp: '[4]quote - site BT services'!$R$18:$R$217
Name ccccccccccccc: #REF!
Name CM_free_move_price: IFERROR(VLOOKUP('[4]quote - usage pricing'!XCD1,'[4]data - PB Free Move'!$A:$P,14,FALSE)*active_forex,"")
Name confidential: '[5]main menu'!$B$33
Name connection_type: '[4]data - main'!$AA$4:$AA$10
Name contract_duration: '[4]data - main'!$AJ$3:$AJ$9
Name cost_pbDID1: #REF!
Name cost_pbDID1: #REF!
Name cost_pbDID1: #REF!
Name cost_pbDID1: #REF!
Name cost_pbDID1: #REF!
Name cost_pbDID2: #REF!
Name cost_pbDID2: #REF!
Name cost_pbDID2: #REF!
Name cost_pbDID2: #REF!
Name cost_pbDID2: #REF!
Name cost_pbVAS1: #REF!
Name cost_pbVAS1: #REF!
Name cost_pbVAS1: #REF!
Name cost_pbVAS1: #REF!
Name cost_pbVAS1: #REF!
Name cost_pbVAS2: #REF!
Name cost_pbVAS2: #REF!
Name cost_pbVAS2: #REF!
Name cost_pbVAS2: #REF!
Name cost_pbVAS2: #REF!
Name cost_pbVAS3: #REF!
Name cost_pbVAS3: #REF!
Name cost_pbVAS3: #REF!
Name cost_pbVAS3: #REF!
Name cost_pbVAS3: #REF!
Name CUR: '[4]data - main'!$AH$5:$AH$6
Name Currency: '[4]main menu'!$H$4
Name currency_selected: '[6]main menu'!$H$4
Name Currency2: '[4]main menu'!$H$4
Name customer_name: '[4]quote - main'!$C$12
Name data: '[4]quote - data table pricing'!$A$5:$P$1531
Name data_table_pricing: '[4]quote - data table pricing'!$A$4:$P$1531
Name DID_avail: '[4]data - main'!$AX$4:$AY$23
Name DID_CT_DA_ZONE_FIND: VLOOKUP('[4]quote - site BT services'!$D1,'[4]data - PB avail'!$E$5:$U$253,16,FALSE)
Name DID_CT_IP_ZONE_FIND: VLOOKUP('[4]quote - site BT services'!$D1,'[4]data - PB avail'!$E$5:$U$253,15,FALSE)
Name DID_CT_SA_ZONE_FIND: VLOOKUP('[4]quote - site BT services'!$D1,'[4]data - PB avail'!$E$5:$U$253,17,FALSE)
Name DID_DA_1_to_9: IF(DID_CT_DA_ZONE_FIND="DIDZ1",DID_MRP_Z1_VLOOKUP_10,IF(DID_CT_DA_ZONE_FIND="DIDZ2",DID_MRP_Z2_VLOOKUP_10,IF(DID_CT_DA_ZONE_FIND="DIDZ3",DID_MRP_Z3_VLOOKUP_10,DID_CT_DA_ZONE_FIND)))
Name DID_DA_10_to_99: IF(DID_CT_DA_ZONE_FIND="DIDZ1",DID_MRP_Z1_VLOOKUP_100,IF(DID_CT_DA_ZONE_FIND="DIDZ2",DID_MRP_Z2_VLOOKUP_100,IF(DID_CT_DA_ZONE_FIND="DIDZ3",DID_MRP_Z3_VLOOKUP_100,DID_CT_DA_ZONE_FIND)))
Name DID_DA_100_to_999: IF(DID_CT_DA_ZONE_FIND="DIDZ1",DID_MRP_Z1_VLOOKUP_1000,IF(DID_CT_DA_ZONE_FIND="DIDZ2",DID_MRP_Z2_VLOOKUP_1000,IF(DID_CT_DA_ZONE_FIND="DIDZ3",DID_MRP_Z3_VLOOKUP_1000,DID_CT_DA_ZONE_FIND)))
Name DID_DA_1000: IF(DID_CT_DA_ZONE_FIND="DIDZ1",DID_MRP_Z1_VLOOKUP_10000,IF(DID_CT_DA_ZONE_FIND="DIDZ2",DID_MRP_Z2_VLOOKUP_10000,IF(DID_CT_DA_ZONE_FIND="DIDZ3",DID_MRP_Z3_VLOOKUP_10000,DID_CT_DA_ZONE_FIND)))
Name DID_MRP_OUTPUT_1_to_9: IF('[4]quote - site BT services'!XEW1="Dedicated Access",DID_DA_1_to_9,IF('[4]quote - site BT services'!XEW1="Switched Access",DID_SA_1_to_9,DID_IP_1_to_9))
Name DID_MRP_OUTPUT_10_to_99: IF('[4]quote - site BT services'!XEW1="Dedicated Access",DID_DA_10_to_99,IF('[4]quote - site BT services'!XEW1="Switched Access",DID_SA_10_to_99,DID_IP_10_to_99))
Name DID_MRP_OUTPUT_100_to_999: IF('[4]quote - site BT services'!XEW1="Dedicated Access",DID_DA_100_to_999,IF('[4]quote - site BT services'!XEW1="Switched Access",DID_SA_100_to_999,DID_IP_100_to_999))
Name DID_MRP_OUTPUT_1000: IF('[4]quote - site BT services'!XEW1="Dedicated Access",DID_DA_1000,IF('[4]quote - site BT services'!XEW1="Switched Access",DID_SA_1000,DID_IP_1000))
Name DID_MRP_Z1_VLOOKUP_10: (VLOOKUP("DID Z1 10",'[4]data - Portal PB other'!$B$8:$S$26,18,FALSE)*active_forex)
Name DID_MRP_Z1_VLOOKUP_100: (VLOOKUP("DID Z1 100",'[4]data - Portal PB other'!$B$8:$S$26,18,FALSE)*active_forex)

Sheet Main Menu
D1: Voice Price Book
D2: SITA Voice Price Book Year 21 - v1.0
B7: =INDEX(MenuItems,'[8]Main menu'!$A$7,0) -> #NAME? | D7: PBy20 STANDARD PRICE BOOK
P10: Access
D11: Contact Center
D12: (All CC Services follow VACS1 Program except IN and NCM) | Q12: >> PSTN Termination
E14: >> PSTN call collection
E16: >> Toll Free call collection
P17: Reference Information
E18: >> UIFN call collection
Q19: >> Country & destination codes
E20: >> Toll Share surcharges
E24: >> Network Contact Manager (NCM)

Sheet PSTN Termination
B1: >> Main Menu
B3: PSTN Termination (Contact Center)
B4: PILOT VACS1 Schedule
B7: All rates in USD
B8: All prices exclude VAT and apply at all times of day.
F11: PSTN Termination
B12: Code | C12: Collecting Country | D12: ISO Code | E12: Termination | F12: Per minute
B13: SURPSTN AFG | C13: Afghanistan | D13: AFG | F13: 0.1578
B14: SURPSTN AFG MOB | C14: Afghanistan | D14: AFG | E14: MOB | F14: 0.1578
B15: SURPSTN ALB | C15: Albania | D15: ALB | F15: 0.164
B16: SURPSTN ALB MOB | C16: Albania | D16: ALB | E16: MOB | F16: 0.4305
B17: SURPSTN DZA | C17: Algeria | D17: DZA | F17: 0.0625
B18: SURPSTN DZA MOB | C18: Algeria | D18: DZA | E18: MOB | F18: 0.7026
B19: SURPSTN ASM | C19: American Samoa | D19: ASM | F19: 1.3021
B20: SURPSTN ASM MOB | C20: American Samoa | D20: ASM | E20: MOB | F20: 1.3021
B21: SURPSTN AND | C21: Andorra | D21: AND | F21: 0.0203
B22: SURPSTN AND MOB | C22: Andorra | D22: AND | E22: MOB | F22: 0.137
B23: SURPSTN AGO | C23: Angola | D23: AGO | F23: 0.0497
B24: SURPSTN AGO MOB | C24: Angola | D24: AGO | E24: MOB | F24: 0.1977
B25: SURPSTN AIA | C25: Anguilla | D25: AIA | F25: 0.2545
B26: SURPSTN AIA MOB | C26: Anguilla | D26: AIA | E26: MOB | F26: 0.2545
B27: SURPSTN ATA | C27: Antarctica | D27: ATA | F27: 1.4002
B28: SURPSTN ATA MOB | C28: Antarctica | D28: ATA | E28: MOB | F28: 1.4002
B29: SURPSTN ATG | C29: Antigua & Barbuda | D29: ATG | F29: 0.3004
B30: SURPSTN ATG MOB | C30: Antigua & Barbuda | D30: ATG | E30: MOB | F30: 0.3004
B31: SURPSTN ARG | C31: Argentina | D31: ARG | F31: 0.0124
B32: SURPSTN ARG MOB | C32: Argentina | D32: ARG | E32: MOB | F32: 0.1799
B33: SURPSTN ARM | C33: Armenia | D33: ARM | F33: 0.2165
B34: SURPSTN ARM MOB | C34: Armenia | D34: ARM | E34: MOB | F34: 0.2354
B35: SURPSTN ABW | C35: Aruba | D35: ABW | F35: 0.1104
B36: SURPSTN ABW MOB | C36: Aruba | D36: ABW | E36: MOB | F36: 0.2285
B37: SURPSTN AUS | C37: Australia | D37: AUS | F37: 0.0117
B38: SURPSTN AUS MOB | C38: Australia | D38: AUS | E38: MOB | F38: 0.0403
B39: SURPSTN AUT | C39: Austria | D39: AUT | F39: 0.0057
B40: SURPSTN AUT MOB | C40: Austria | D40: AUT | E40: MOB | F40: 0.0165
B41: SURPSTN AZE | C41: Azerbaijan | D41: AZE | F41: 0.2012
B42: SURPSTN AZE MOB | C42: Azerbaijan | D42: AZE | E42: MOB | F42: 0.3243
B43: SURPSTN BHS | C43: Bahamas | D43: BHS | F43: 0.2542
B44: SURPSTN BHS MOB | C44: Bahamas | D44: BHS | E44: MOB | F44: 0.2542
B45: SURPSTN BHR | C45: Bahrain | D45: BHR | F45: 0.1285
...

Sheet PSTN
B1: >> Main Menu | S1: =_xlfn.TEXTJOIN(",",,R1:R4)
B3: Contact Center - PSTN Call Collection Prices
B4: PILOT VACS1 Schedule
B7: All rates in USD
B8: All prices exclude VAT and apply at all times of day.
B9: 'na' indicates not available as a standard service, please see Voice Availaibility Matrix.
B10: TPM charges not applicable to Advance PSTN Call Usage
G15: Fixed Charges Per Number
F16: PSTN Call Usage | G16: Code | H16: Installation | I16: Rental
A17: unique ID | B17: Code Usage | C17: Collecting Country | D17: ISO Code | E17: Origination | F17: Per minute | G17: Per Number | H17: One time | I17: Monthly
A18: PSTN ALB | B18: PSTN ALB | C18: Albania | D18: ALB | F18: 0.0273 | G18: PSTNNUM ALB | H18: 89.6 | I18: 13.44
A19: PSTN DZA | B19: PSTN ALB MOB | C19: Albania | D19: ALB | E19: MOB | F19: 0.0273
A20: PSTN AGO | B20: PSTN DZA | C20: Algeria | D20: DZA | F20: 0.0728 | G20: PSTNNUM DZA | H20: 93.57 | I20: 14.875
A21: PSTN ARG | B21: PSTN DZA MOB | C21: Algeria | D21: DZA | E21: MOB | F21: 0.0728
A22: PSTN AUS | B22: PSTN AGO | C22: Angola | D22: =VLOOKUP(C22,'Country & dest. codes'!$B$7:$F$250,5,0) -> AGO | F22: 0.0363 | G22: PSTNNUM AGO | H22: 89.6 | I22: 44.8
A23: PSTN AUT | B23: PSTN AGO MOB | C23: Angola | D23: =VLOOKUP(C23,'Country & dest. codes'!$B$7:$F$250,5,0) -> AGO | E23: MOB | F23: 0.0363
A24: PSTN BGD | B24: PSTN ARG | C24: Argentina | D24: ARG | F24: 0.0095 | G24: PSTNNUM ARG | H24: 93.57 | I24: 12.21
A25: PSTN BLR | B25: PSTN ARG MOB | C25: Argentina | D25: ARG | E25: MOB | F25: 0.0095
A26: PSTN BEL | B26: PSTN AUS | C26: Australia | D26: AUS | F26: 0.006 | G26: PSTNNUM AUS | H26: 93.57 | I26: 12.21
A27: PSTN BEN | B27: PSTN AUS MOB | C27: Australia | D27: AUS | E27: MOB | F27: 0.006
A28: PSTN BIH | B28: PSTN AUT | C28: Austria | D28: AUT | F28: 0.006 | G28: PSTNNUM AUT | H28: 93.57 | I28: 4.07
A29: PSTN BRA | B29: PSTN AUT MOB | C29: Austria | D29: AUT | E29: MOB | F29: 0.006
A30: PSTN BGR | B30: PSTN BGD | C30: Bangladesh | D30: BGD | F30: 0.1067 | G30: PSTNNUM BGD | H30: 93.57 | I30: 33.6
A31: PSTN BFA | B31: PSTN BGD MOB | C31: Bangladesh | D31: BGD | E31: MOB | F31: 0.1067
A32: PSTN KHM | B32: PSTN BLR | C32: Belarus | D32: =VLOOKUP(C32,'Country & dest. codes'!$B$7:$F$250,5,0) -> BLR | F32: 0.0343 | G32: PSTNNUM BLR | H32: 134.4 | I32: 89.6
A33: PSTN CMR | B33: PSTN BLR MOB | C33: Belarus | D33: =VLOOKUP(C33,'Country & dest. codes'!$B$7:$F$250,5,0) -> BLR | E33: MOB | F33: 0.0343
A34: PSTN CAN | B34: PSTN BEL | C34: Belgium | D34: BEL | F34: 0.006 | G34: PSTNNUM BEL | H34: 93.57 | I34: 0.68
A35: PSTN CYM | B35: PSTN BEL MOB | C35: Belgium | D35: BEL | E35: MOB | F35: 0.006
A36: PSTN CHL | B36: PSTN BEN | C36: Benin | D36: BEN | F36: 0.2429 | G36: PSTNNUM BEN | H36: 93.57 | I36: 89.6
A37: PSTN CHN | B37: PSTN BEN MOB | C37: Benin | D37: BEN | E37: MOB | F37: 0.2429
A38: PSTN COL | B38: PSTN BIH | C38: Bosnia | D38: BIH | F38: 0.0269 | G38: PSTNNUM BIH | H38: 89.6 | I38: 19.2
A39: PSTN CRI | B39: PSTN BIH MOB | C39: Bosnia | D39: BIH | E39: MOB | F39: 0.0269
A40: PSTN HRV | B40: PSTN BRA | C40: Brazil | D40: BRA | F40: 0.0095 | G40: PSTNNUM BRA | H40: 93.57 | I40: 12.21
A41: PSTN CYP | B41: PSTN BRA MOB | C41: Brazil | D41: BRA | E41: MOB | F41: 0.0095
A42: PSTN CZE | B42: PSTN BGR | C42: Bulgaria | D42: BGR | F42: 0.0095 | G42: PSTNNUM BGR | H42: 93.57 | I42: 12.21
A43: PSTN DNK | B43: PSTN BGR MOB | C43: Bulgaria | D43: BGR | E43: MOB | F43: 0.0095
A44: PSTN DOM | B44: PSTN BFA | C44: Burkina Faso | D44: BFA | F44: 0.3614 | G44: PSTNNUM BFA | H44: 134.4 | I44: 89.25
A45: PSTN SLV | B45: PSTN BFA MOB | C45: Burkina Faso | D45: BFA | E45: MOB | F45: 0.3614
A46: PSTN EST | B46: PSTN KHM | C46: Cambodia | D46: KHM | F46: 0.2861 | G46: PSTNNUM KHM | H46: 179.2 | I46: 89.6
A47: PSTN FIN | B47: PSTN KHM MOB | C47: Cambodia | D47: KHM | E47: MOB | F47: 0.2861
...

Sheet Toll Free
B1: >> Main Menu
B3: Contact Center - Toll Free Call Collection Prices
B4: PILOT VACS1 Schedule
B7: All rates in USD
B8: All prices exclude VAT and apply at all times of day.
B9: 'na' indicates not available as a standard service, please see Voice Availaibility Matrix.
B10: TPM charges not applicable to Advance Toll Free Call Usage
G14: Fixed Charges Per Number
F15: Toll Free Call Usage | G15: Code | H15: Installation | I15: Rental
B16: Code Usage | C16: Collecting Country | D16: ISO Code | E16: Origination | F16: Per minute | G16: Per Number | H16: One time | I16: Monthly
B17: TF ARG | C17: Argentina | D17: ARG | F17: 0.0476 | G17: =IF(H17="","","TFNUM"&" "&D17) -> TFNUM ARG | H17: 168.43 | I17: 12.2135
B18: TF ARG MOB | C18: Argentina | D18: ARG | E18: MOB | F18: 0.0476
B19: TF AUS | C19: Australia | D19: AUS | F19: 0.0134 | G19: =IF(H19="","","TFNUM"&" "&D19) -> TFNUM AUS | H19: 168.43 | I19: 16.2815
B20: TF AUS MOB | C20: Australia | D20: AUS | E20: MOB | F20: 0.022
B21: TF AUT | C21: Austria | D21: AUT | F21: 0.0415 | G21: =IF(H21="","","TFNUM"&" "&D21) -> TFNUM AUT | H21: 168.43 | I21: 12.2135
B22: TF AUT MOB | C22: Austria | D22: AUT | E22: MOB | F22: 0.1338
B23: TF BHS | C23: Bahamas | D23: BHS | F23: 0.1227 | G23: =IF(H23="","","TFNUM"&" "&D23) -> TFNUM BHS | H23: 206.64 | I23: 28.495
B24: TF BHS MOB | C24: Bahamas | D24: BHS | E24: MOB | F24: 0.1227
B25: TF BLR | C25: Belarus | D25: BLR | F25: 0.4104 | G25: =IF(H25="","","TFNUM"&" "&D25) -> TFNUM BLR | H25: 168.43 | I25: 28.495
B26: TF BLR MOB | C26: Belarus | D26: BLR | E26: MOB | F26: 0.4104
B27: TF BEL | C27: Belgium | D27: BEL | F27: 0.0207 | G27: =IF(H27="","","TFNUM"&" "&D27) -> TFNUM BEL | H27: 168.43 | I27: 12.2135
B28: TF BEL MOB | C28: Belgium | D28: BEL | E28: MOB | F28: 0.2149
B29: TF BLZ | C29: Belize | D29: BLZ | F29: 0.2708 | G29: =IF(H29="","","TFNUM"&" "&D29) -> TFNUM BLZ | H29: 168.43 | I29: 28.5
B30: TF BLZ MOB | C30: Belize | D30: BLZ | E30: MOB | F30: 0.2708
B31: TF BMU | C31: Bermuda | D31: BMU | F31: 0.0843 | G31: =IF(H31="","","TFNUM"&" "&D31) -> TFNUM BMU | H31: 168.43 | I31: 28.5
B32: TF BMU MOB | C32: Bermuda | D32: BMU | E32: MOB | F32: 0.0843
B33: TF BWA | C33: Botswana | D33: BWA | F33: 0.5022 | G33: =IF(H33="","","TFNUM"&" "&D33) -> TFNUM BWA | H33: 100.8 | I33: 28.495
B34: TF BWA MOB | C34: Botswana | D34: BWA | E34: MOB | F34: 0.5022
B35: TF BRA | C35: Brazil | D35: BRA | F35: 0.0124 | G35: =IF(H35="","","TFNUM"&" "&D35) -> TFNUM BRA | H35: 440.8375 | I35: 67.2
B36: TF BRA MOB | C36: Brazil | D36: BRA | E36: MOB | F36: 0.0477
B37: TF BRN | C37: Brunei | D37: BRN | F37: 0.2708 | G37: =IF(H37="","","TFNUM"&" "&D37) -> TFNUM BRN | H37: 168.43 | I37: 28.495
B38: TF BRN MOB | C38: Brunei | D38: BRN | E38: MOB | F38: 0.2708
B39: TF BGR | C39: Bulgaria | D39: BGR | F39: 0.0414 | G39: =IF(H39="","","TFNUM"&" "&D39) -> TFNUM BGR | H39: 168.43 | I39: 28.495
B40: TF BGR MOB | C40: Bulgaria | D40: BGR | E40: MOB | F40: 0.1559
B41: TF KHM | C41: Cambodia | D41: =VLOOKUP(C41,PSTN!C:D,2,0) -> KHM | F41: 0.4041 | G41: =IF(H41="","","TFNUM"&" "&D41) -> TFNUM KHM | H41: 134.4 | I41: 134.4
B42: TF KHM MOB | C42: Cambodia | D42: =VLOOKUP(C42,PSTN!C:D,2,0) -> KHM | E42: MOB | F42: 0.4041
B43: TF CAN | C43: Canada | D43: CAN | F43: 0.0083 | G43: =IF(H43="","","TFNUM"&" "&D43) -> TFNUM CAN | H43: 168.43 | I43: 12.2135
B44: TF CAN MOB | C44: Canada | D44: CAN | E44: MOB | F44: 0.0083
B45: TF CHL | C45: Chile | D45: CHL | F45: 0.0313 | G45: =IF(H45="","","TFNUM"&" "&D45) -> TFNUM CHL | H45: 168.43 | I45: 26.88
B46: TF CHL MOB | C46: Chile | D46: CHL | E46: MOB | F46: 0.0313
...

Sheet UIFN
B2: >> Main Menu
B4: Contact Center - UIFN Call Collection Prices
B5: PILOT VACS1 Schedule
B8: All rates in USD
B9: All prices exclude VAT and apply at all times of day.
B10: 'na' indicates not available as a standard service, please see Voice Availaibility Matrix.
B11: TPM charges not applicable to Advance UIFN Call Usage
G15: Fixed Charges Per Number
F16: UIFN Call Usage | G16: Code | H16: Installation | I16: Rental
B17: Code Usage | C17: Collecting Country | D17: ISO Code | E17: Origination | F17: Per minute | G17: Per Number | H17: One time | I17: Monthly
A18: UIFN ARG | B18: UIFN ARG | C18: Argentina | D18: ARG | F18: 0.1467 | G18: =IF(H18="","","UIFNNUM"&" "&D18) -> UIFNNUM ARG | H18: 233.94 | I18: 16.28
A19: UIFN ARG MOB | B19: UIFN ARG MOB | C19: Argentina | D19: ARG | E19: MOB | F19: 0.1467 | G19: =IF(H19="","","UIFNNUM"&" "&D19)
A20: UIFN BLR | B20: UIFN BLR | C20: Belarus | D20: BLR | F20: 0.3496 | G20: =IF(H20="","","UIFNNUM"&" "&D20) -> UIFNNUM BLR | H20: 380.8 | I20: 20.35
A21: UIFN BLR MOB | B21: UIFN BLR MOB | C21: Belarus | D21: BLR | E21: MOB | F21: 0.3496 | G21: =IF(H21="","","UIFNNUM"&" "&D21)
A22: UIFN LVA | B22: UIFN LVA | C22: Latvia | D22: LVA | F22: 0.1618 | G22: =IF(H22="","","UIFNNUM"&" "&D22) -> UIFNNUM LVA | H22: 380.8 | I22: 16.28
A23: UIFN LVA MOB | B23: UIFN LVA MOB | C23: Latvia | D23: LVA | E23: MOB | F23: 0.1618 | G23: =IF(H23="","","UIFNNUM"&" "&D23)
A24: UIFN NZL | B24: UIFN NZL | C24: New Zealand | D24: NZL | F24: 0.0602 | G24: =IF(H24="","","UIFNNUM"&" "&D24) -> UIFNNUM NZL | H24: 380.8 | I24: 20.35
A25: UIFN NZL MOB | B25: UIFN NZL MOB | C25: New Zealand | D25: NZL | E25: MOB | F25: 0.3687 | G25: =IF(H25="","","UIFNNUM"&" "&D25)
A26: UIFN BEL | B26: UIFN BEL | C26: Belgium | D26: BEL | F26: 0.0213 | G26: =IF(H26="","","UIFNNUM"&" "&D26) -> UIFNNUM BEL | H26: 233.94 | I26: 16.28
A27: UIFN BEL MOB | B27: UIFN BEL MOB | C27: Belgium | D27: BEL | E27: MOB | F27: 0.2117 | G27: =IF(H27="","","UIFNNUM"&" "&D27)
A28: UIFN BRA | B28: UIFN BRA | C28: Brazil | D28: BRA | F28: 0.1207 | G28: =IF(H28="","","UIFNNUM"&" "&D28) -> UIFNNUM BRA | H28: 233.94 | I28: 24.43
A29: UIFN BRA MOB | B29: UIFN BRA MOB | C29: Brazil | D29: BRA | E29: MOB | F29: 0.3484 | G29: =IF(H29="","","UIFNNUM"&" "&D29)
A30: UIFN BGR | B30: UIFN BGR | C30: Bulgaria | D30: BGR | F30: 0.1473 | G30: =IF(H30="","","UIFNNUM"&" "&D30) -> UIFNNUM BGR | H30: 233.94 | I30: 20.35
A31: UIFN BGR MOB | B31: UIFN BGR MOB | C31: Bulgaria | D31: BGR | E31: MOB | F31: 0.1473 | G31: =IF(H31="","","UIFNNUM"&" "&D31)
A32: UIFN PHL | B32: UIFN PHL | C32: Philippines | D32: PHL | F32: 0.2062 | G32: =IF(H32="","","UIFNNUM"&" "&D32) -> UIFNNUM PHL | H32: 380.8 | I32: 20.35
A33: UIFN PHL MOB | B33: UIFN PHL MOB | C33: Philippines | D33: PHL | E33: MOB | F33: 0.2062 | G33: =IF(H33="","","UIFNNUM"&" "&D33)
A34: UIFN CHN | B34: UIFN CHN | C34: China | D34: CHN | F34: 0.2566 | G34: =IF(H34="","","UIFNNUM"&" "&D34) -> UIFNNUM CHN | H34: 233.94 | I34: 24.43
A35: UIFN CHN MOB | B35: UIFN CHN MOB | C35: China | D35: CHN | E35: MOB | F35: 0.2566 | G35: =IF(H35="","","UIFNNUM"&" "&D35)
A36: UIFN COL | B36: UIFN COL | C36: Colombia | D36: COL | F36: 0.2368 | G36: =IF(H36="","","UIFNNUM"&" "&D36) -> UIFNNUM COL | H36: 233.94 | I36: 16.28
A37: UIFN COL MOB | B37: UIFN COL MOB | C37: Colombia | D37: COL | E37: MOB | F37: 0.2262 | G37: =IF(H37="","","UIFNNUM"&" "&D37)
A38: UIFN HRV | B38: UIFN HRV | C38: Croatia | D38: HRV | F38: 0.2518 | G38: =IF(H38="","","UIFNNUM"&" "&D38) -> UIFNNUM HRV | H38: 233.94 | I38: 20.35
A39: UIFN HRV MOB | B39: UIFN HRV MOB | C39: Croatia | D39: HRV | E39: MOB | F39: 0.2518 | G39: =IF(H39="","","UIFNNUM"&" "&D39)
A40: UIFN CYP | B40: UIFN CYP | C40: Cyprus | D40: CYP | F40: 0.0826 | G40: =IF(H40="","","UIFNNUM"&" "&D40) -> UIFNNUM CYP | H40: 233.94 | I40: 16.28
A41: UIFN CYP MOB | B41: UIFN CYP MOB | C41: Cyprus | D41: CYP | E41: MOB | F41: 0.0826 | G41: =IF(H41="","","UIFNNUM"&" "&D41)
A42: UIFN POL | B42: UIFN POL | C42: Poland | D42: POL | F42: 0.0483 | G42: =IF(H42="","","UIFNNUM"&" "&D42) -> UIFNNUM POL | H42: 95.2 | I42: 16.28
A43: UIFN POL MOB | B43: UIFN POL MOB | C43: Poland | D43: POL | E43: MOB | F43: 0.0483 | G43: =IF(H43="","","UIFNNUM"&" "&D43)
A44: UIFN SVN | B44: UIFN SVN | C44: Slovenia | D44: SVN | F44: 0.1301 | G44: =IF(H44="","","UIFNNUM"&" "&D44) -> UIFNNUM SVN | H44: 380.8 | I44: 24.43
A45: UIFN SVN MOB | B45: UIFN SVN MOB | C45: Slovenia | D45: SVN | E45: MOB | F45: 0.1301 | G45: =IF(H45="","","UIFNNUM"&" "&D45)
A46: UIFN KOR | B46: UIFN KOR | C46: South Korea | D46: KOR | F46: 0.1111 | G46: =IF(H46="","","UIFNNUM"&" "&D46) -> UIFNNUM KOR | H46: 380.8 | I46: 24.43
A47: UIFN KOR MOB | B47: UIFN KOR MOB | C47: South Korea | D47: KOR | E47: MOB | F47: 0.1111 | G47: =IF(H47="","","UIFNNUM"&" "&D47)
...

Sheet Toll Share Surcharge
B2: >> Main Menu
B4: Contact Center - Toll & Revenue Share Surcharges
B5: PILOT VACS1 Schedule
B8: All rates in USD
B9: All prices exclude VAT and apply at all times of day.
B10: 'na' indicates not available as a standard service, please see Voice Availaibility Matrix.
B11: TPM charges not applicable to Advance Toll Shared Call Usage
H14: Toll Shared Call Usage | I14: Fixed Charges Per Number
I15: Code | J15: Installation | K15: Rental
B16: Code | C16: Collecting Country | D16: ISO Code | E16: number type | F16: Originating Pricing Zone | G16: Origination | H16: Per minute | I16: Per Number | J16: One time | K16: Monthly
B17: TS ARG 810 | C17: Argentina | D17: ARG | E17: Toll Share | F17: Argentina810 | H17: 0.0238 | I17: TSNUM ARG 810 | J17: 168.43 | K17: 17.1553
B18: TS ARG 810 MOB | C18: Argentina | D18: ARG | E18: Toll Share | F18: Argentina810 | G18: MOB | H18: 0.0238
B19: TS AUS 13 | C19: Australia | D19: AUS | E19: Toll Share | F19: Australia13 | H19: 0.014 | I19: TSNUM AUS 13 | J19: 179.2 | K19: 44.8
B20: TS AUS 13 MOB | C20: Australia | D20: AUS | E20: Toll Share | F20: Australia13 | G20: MOB | H20: 0.014
B21: TS AUS 1300 | C21: Australia | D21: AUS | E21: Toll Share | F21: Australia1300 | H21: 0.014 | I21: TSNUM AUS 1300 | J21: 168.43 | K21: 17.1553
B22: TS AUS 1300 MOB | C22: Australia | D22: AUS | E22: Toll Share | F22: Australia1300 | G22: MOB | H22: 0.014
B23: TS AUT 0720 | C23: Austria | D23: AUT | E23: Toll Share | F23: Austria0720 | H23: 0 | I23: TSNUM AUT 0720 | J23: 168.43 | K23: 53.0254
B24: TS AUT 0720 MOB | C24: Austria | D24: AUT | E24: Toll Share | F24: Austria0720 | G24: MOB | H24: 0
B25: TS AUT 810-stufe3 | C25: Austria | D25: AUT | E25: Toll Share | F25: Austria810-stufe3 | H25: 0 | I25: TSNUM AUT 810-stufe3 | J25: 168.43 | K25: 17.1553
B26: TS AUT 810-stufe3 MOB | C26: Austria | D26: AUT | E26: Toll Share | F26: Austria810-stufe3 | G26: MOB | H26: 0
B27: TS AUT 810-stufe5 | C27: Austria | D27: AUT | E27: Toll Share | F27: Austria810-stufe5 | H27: 0 | I27: TSNUM AUT 810-stufe5 | J27: 168.43 | K27: 17.1553
B28: TS AUT 810-stufe5 MOB | C28: Austria | D28: AUT | E28: Toll Share | F28: Austria810-stufe5 | G28: MOB | H28: 0
B29: TS AUT 810-stufe6 | C29: Austria | D29: AUT | E29: Toll Share | F29: Austria810-stufe6 | H29: 0 | I29: TSNUM AUT 810-stufe6 | J29: 168.43 | K29: 17.1553
B30: TS AUT 810-stufe6 MOB | C30: Austria | D30: AUT | E30: Toll Share | F30: Austria810-stufe6 | G30: MOB | H30: 0
B31: TS AUT 820-stufe3 | C31: Austria | D31: AUT | E31: Toll Share | F31: Austria820-stufe3 | H31: 0 | I31: TSNUM AUT 820-stufe3 | J31: 168.43 | K31: 17.1553
B32: TS AUT 820-stufe3 MOB | C32: Austria | D32: AUT | E32: Toll Share | F32: Austria820-stufe3 | G32: MOB | H32: 0
B33: TS AUT 820-stufe4 | C33: Austria | D33: AUT | E33: Toll Share | F33: Austria820-stufe4 | H33: 0 | I33: TSNUM AUT 820-stufe4 | J33: 168.43 | K33: 17.1553
B34: TS AUT 820-stufe4 MOB | C34: Austria | D34: AUT | E34: Toll Share | F34: Austria820-stufe4 | G34: MOB | H34: 0
B35: TS BEL 070 | C35: Belgium | D35: BEL | E35: Toll Share | F35: Belgium070 | H35: 0 | I35: TSNUM BEL 070 | J35: 168.43 | K35: 53.0254
B36: TS BEL 070 MOB | C36: Belgium | D36: BEL | E36: Toll Share | F36: Belgium070 | G36: MOB | H36: 0
B37: TS BEL 078 | C37: Belgium | D37: BEL | E37: Toll Share | F37: Belgium078 | H37: 0.006 | I37: TSNUM BEL 078 | J37: 168.43 | K37: 53.0254
B38: TS BEL 078 MOB | C38: Belgium | D38: BEL | E38: Toll Share | F38: Belgium078 | G38: MOB | H38: 0.006
B39: TS BGR 070 | C39: Bulgaria | D39: BGR | E39: Toll Share | F39: Bulgaria070 | H39: 0.0414 | I39: TSNUM BGR 070 | J39: 168.43 | K39: 53.0254
B40: TS BGR 070 MOB | C40: Bulgaria | D40: BGR | E40: Toll Share | F40: Bulgaria070 | G40: MOB | H40: 0.0414
B41: TS CHN 400 | C41: China | D41: CHN | E41: Toll Share | F41: China400 | H41: 0.0651 | I41: TSNUM CHN 400 | J41: 168.43 | K41: 44.8
B42: TS CHN 400 MOB | C42: China | D42: CHN | E42: Toll Share | F42: China400 | G42: MOB | H42: 0.0651
B43: TS CZE 0810 | C43: Czech Republic | D43: CZE | E43: Toll Share | F43: CzechRepublic0810 | H43: 0.0093 | I43: TSNUM CZE 0810 | J43: 168.43 | K43: 17.1553
B44: TS CZE 0810 MOB | C44: Czech Republic | D44: CZE | E44: Toll Share | F44: CzechRepublic0810 | G44: MOB | H44: 0.0093
B45: TS DNK 701 | C45: Denmark | D45: DNK | E45: Toll Share | F45: Denmark701 | H45: 0.0024 | I45: TSNUM DNK 701 | J45: 168.43 | K45: 53.0254
B46: TS DNK 701 MOB | C46: Denmark | D46: DNK | E46: Toll Share | F46: Denmark701 | G46: MOB | H46: 0.0024
...

Sheet Country & dest. codes
B1: >> Main Menu
B3: regions & call types | G3: Business Talk Margin Tool v15.38
B6: region by country | K6: list of regions | N6: list of call types
B7: country | C7: region | D7: customer-specific region | E7: billing country code | F7: ISO-3 country code | G7: ISO-2 country code | H7: country (repeated for VLOOKUPs) | K7: region | L7: description | N7: call type | O7: description
B8: Afghanistan | C8: RoW 2 | E8: AFG | F8: AFG | G8: AF | H8: Afghanistan | K8: Eur 1 | L8: major Europe | N8: fixed | O8: calls to fixed lines
B9: Albania | C9: Eur 2 | E9: ALB | F9: ALB | G9: AL | H9: Albania | K9: Eur 2 | L9: minor Europe | N9: mobile | O9: calls to mobiles
B10: Algeria | C10: RoW 2 | E10: DZA | F10: DZA | G10: DZ | H10: Algeria | K10: NAM | L10: North America | N10: NGN | O10: calls to non-geographic numbers (e.g. toll free, shared cost)
B11: All other routes | C11: RoW 2 | E11: AOR | F11: na | G11: na | H11: All other routes | K11: LAM | L11: Latin America | N11: on-net | O11: on-net calls between customer sites
B12: American Samoa | C12: RoW 2 | E12: ASM | F12: ASM | G12: AS | H12: American Samoa | K12: Asia 1 | L12: major Asia | N12: access | O12: SA Surcharge
B13: Andorra | C13: Eur 2 | E13: AND | F13: AND | G13: AD | H13: Andorra | K13: Asia 2 | L13: minor Asia | N13: ISDN | O13: international ISDN calls
B14: Angola | C14: RoW 2 | E14: AGO | F14: AGO | G14: AO | H14: Angola | K14: RoW 1 | L14: major Rest Of World
B15: Anguilla | C15: RoW 2 | E15: AIA | F15: AIA | G15: AI | H15: Anguilla | K15: RoW 2 | L15: minor Rest Of World
B16: Antarctica | C16: RoW 2 | E16: ATA | F16: ATA | G16: AQ | H16: Antarctica | K16: NGN | L16: non-geographic number
B17: Antigua & Barbuda | C17: RoW 2 | E17: ATG | F17: ATG | G17: AG | H17: Antigua & Barbuda | K17: Satellite | L17: satellite
B18: Argentina | C18: LAM | E18: ARG | F18: ARG | G18: AR | H18: Argentina
B19: Armenia | C19: RoW 1 | E19: ARM | F19: ARM | G19: AM | H19: Armenia
B20: Aruba | C20: RoW 2 | E20: ABW | F20: ABW | G20: AW | H20: Aruba
B21: Ascension Is | C21: RoW 2 | E21: ASC | F21: ASC | G21: AC | H21: Ascension Is
B22: Australia | C22: Asia 1 | E22: AUS | F22: AUS | G22: AU | H22: Australia
B23: Austria | C23: Eur 1 | E23: AUT | F23: AUT | G23: AT | H23: Austria
B24: Azerbaijan | C24: Eur 2 | E24: AZE | F24: AZE | G24: AZ | H24: Azerbaijan
B25: Bahamas | C25: RoW 2 | E25: BHS | F25: BHS | G25: BS | H25: Bahamas
B26: Bahrain | C26: RoW 1 | E26: BHR | F26: BHR | G26: BH | H26: Bahrain
B27: Bangladesh | C27: RoW 2 | E27: BGD | F27: BGD | G27: BD | H27: Bangladesh
B28: Barbados | C28: RoW 2 | E28: BRB | F28: BRB | G28: BB | H28: Barbados
B29: Belarus | C29: Eur 2 | E29: BLR | F29: BLR | G29: BY | H29: Belarus
... B61: Cuba | C61: RoW 2 | E61: CUB | F61: CUB | G61: CU | H61: Cuba
B62: Curaçao | C62: RoW 2 | E62: CUW | F62: CUW | H62: Curaçao
B63: Cyprus | C63: RoW 2 | E63: CYP | F63: CYP | G63: CY | H63: Cyprus
B64: Czech Republic | C64: Eur 2 | E64: CZE | F64: CZE | G64: CZ | H64: Czech Republic
B65: Denmark | C65: Eur 1 | E65: DNK | F65: DNK | G65: DK | H65: Denmark
B66: Diego Garcia | C66: RoW 2 | E66: IOT | F66: DGA | G66: IO | H66: Diego Garcia
B67: Djibouti | C67: RoW 2 | E67: DJI | F67: DJI | G67: DJ | H67: Djibouti
B68: Dominica | C68: RoW 2 | E68: DMA | F68: DMA | G68: DM | H68: Dominica
B69: Dominican Republic | C69: RoW 2 | E69: DOM | F69: DOM | G69: DO | H69: Dominican Republic
B70: East Timor | C70: RoW 2 | E70: TLS | F70: TLS | G70: TL | H70: East Timor
B71: Ecuador | C71: RoW 2 | E71: ECU | F71: ECU | G71: EC | H71: Ecuador
B72: Egypt | C72: RoW 1 | E72: EGY | F72: EGY | G72: EG | H72: Egypt
B73: El Salvador | C73: RoW 2 | E73: SLV | F73: SLV | G73: SV | H73: El Salvador
B74: Equatorial Guinea | C74: RoW 2 | E74: GNQ | F74: GNQ | G74: GQ | H74: Equatorial Guinea
...

Sheet country code mapping
A1: country | B1: ISO 3 Code | C1: ISO 2 Code | G1: Count of country
A2: Afghanistan | B2: AFG | C2: AF | G2: ISO 2 Code | H2: country | I2: Total
A3: Albania | B3: ALB | C3: AL | G3: AD | H3: Andorra | I3: 1
A4: Algeria | B4: DZA | C4: DZ | G4: AE | H4: United Arab Emirates | I4: 1
A5: American Samoa | B5: ASM | C5: AS | G5: AF | H5: Afghanistan | I5: 1
A6: Andorra | B6: AND | C6: AD | G6: AG | H6: Antigua & Barbuda | I6: 1
A7: Angola | B7: AGO | C7: AO | G7: AI | H7: Anguilla | I7: 1
A8: Anguilla | B8: AIA | C8: AI | G8: AL | H8: Albania | I8: 1
A9: Antarctica | B9: ATA | C9: AQ | G9: AM | H9: Armenia | I9: 1
A10: Antigua & Barbuda | B10: ATG | C10: AG | G10: AO | H10: Angola | I10: 1
A11: Argentina | B11: ARG | C11: AR | G11: AQ | H11: Antarctica | I11: 1
A12: Armenia | B12: ARM | C12: AM | G12: AR | H12: Argentina | I12: 1
A13: Aruba | B13: ABW | C13: AW | G13: AS | H13: American Samoa | I13: 1
A14: Australia | B14: AUS | C14: AU | G14: AT | H14: Austria | I14: 1
... A18: Bahrain | B18: BHR | C18: BH | G18: BA | H18: Bosnia & Herzegovina | I18: 1
A19: Bangladesh | B19: BGD | C19: BD | H19: Bosnia/Herzegovina | I19: 1
A20: Barbados | B20: BRB | C20: BB | H20: Bosnia | I20: 1
A21: Belarus | B21: BLR | C21: BY | G21: BB | H21: Barbados | I21: 1
A22: Belgium | B22: BEL | C22: BE | G22: BD | H22: Bangladesh | I22: 1
A23: Belize | B23: BLZ | C23: BZ | G23: BE | H23: Belgium | I23: 1
A24: Benin | B24: BEN | C24: BJ | G24: BF | H24: Burkina | I24: 1
A25: Bermuda | B25: BMU | C25: BM | H25: Burkina Faso | I25: 1
A26: Bhutan | B26: BTN | C26: BT | G26: BG | H26: Bulgaria | I26: 1
A27: Bolivia | B27: BOL | C27: BO | G27: BH | H27: Bahrain | I27: 1
A28: Bonnaire St Eustache Saba | B28: BES | C28: BQ | G28: BI | H28: Burundi | I28: 1
A29: Bosnia & Herzegovina | B29: BIH | C29: BA | G29: BJ | H29: Benin | I29: 1
A30: Botswana | B30: BWA | C30: BW | G30: BM | H30: Bermuda | I30: 1
A31: Brazil | B31: BRA | C31: BR | G31: BN | H31: Brunei | I31: 1
A32: Brunei | B32: BRN | C32: BN | G32: BO | H32: Bolivia | I32: 1
A33: Bulgaria | B33: BGR | C33: BG | G33: BQ | H33: Bonaire | I33: 1
A34: Burkina Faso | B34: BFA | C34: BF | H34: Bonnaire St Eustache Saba | I34: 1
A35: Burundi | B35: BDI | C35: BI | G35: BR | H35: Brazil | I35: 1
A36: Cambodia | B36: KHM | C36: KH | G36: BS | H36: Bahamas | I36: 1
A37: Cameroon | B37: CMR | C37: CM | G37: BT | H37: Bhutan | I37: 1
A38: Canada | B38: CAN | C38: CA | G38: BW | H38: Botswana | I38: 1
A39: Cape Verde | B39: CPV | C39: CV | G39: BY | H39: Belarus | I39: 1
A40: Cayman Is | B40: CYM | C40: KY | G40: BZ | H40: Belize | I40: 1
A41: Central African Republic | B41: CAF | C41: CF | G41: CA | H41: Canada | I41: 1
A42: Chad | B42: TCD | C42: TD | G42: CD | H42: Congo Dem. Rep. | I42: 1
A43: Chile | B43: CHL | C43: CL | H43: Dem Rep of Congo | I43: 1
...
